Workbook

Sheet ✈ Flights
A1: ✈ AIRLINE DATASET — FLIGHTS TABLE (Contains Dirty Data)
A2: Flight Id | B2: Flight Date | C2: Airline | D2: Origin City | E2: Origin Code | F2: Destination City | G2: Destination Code | H2: Departure Time | I2: Arrival Time | J2: Flight Duration Min | K2: Distance Miles | L2: Ticket Price | M2: Class | N2: Seats Available | O2: Passengers Boarded | P2: Status | Q2: Delay Minutes
A3: FL001 | B3: 2022-08-17 | C3: Delta | D3: Boston | E3: BOS | F3: Denver | G3: DEN | H3: 07:15 | I3: 15:02 | J3: 467 | K3: 719 | L3: 837.9 | M3: First Class | N3: 122 | O3: 104 | P3: On-Time | Q3: 0
A4: FL002 | B4: 2022-07-11 | C4: Southwest | D4: Denver | E4: DEN | F4: Orlando | G4: MCO | H4: 19:00 | I4: 01:17 | J4: 377 | K4: 1114 | L4: 881.94 | M4: First Class | N4: 239 | O4: 157 | P4: On-Time | Q4: 0
A5: FL003 | B5: 2023-07-24 | C5: Delta | D5: Miami | E5: MIA | F5: Charlotte | G5: CLT | H5: 10:30 | I5: 13:19 | J5: 169 | K5: 1181 | L5: 1152.08 | M5: Business | N5: 126 | O5: 61 | P5: On-Time | Q5: 0
A6: FL004 | B6: 2024-01-06 | C6: Alaska | D6: San Diego | E6: SAN | F6: Boston | G6: BOS | H6: 01:45 | I6: 07:49 | J6: 364 | K6: 811 | L6: 1169.89 | M6: Business | N6: 120 | O6: 120 | P6: On-Time | Q6: 0
A7: FL005 | B7: 2024-01-11 | C7: Southwest | D7: Chicago | E7: ORD | F7: Los Angeles | G7: LAX | H7: 21:15 | I7: 01:13 | J7: 238 | K7: 626 | L7: 1037.96 | M7: Economy | N7: 197 | O7: 121 | P7: On-Time | Q7: 0
A8: FL006 | B8: 2024-01-18 | C8: American | D8: San Francisco | E8: SFO | F8: Minneapolis | G8: MSP | H8: 06:30 | I8: 13:59 | J8: 449 | K8: 2954 | L8: 159.97 | M8: First Class | N8: 143 | O8: 118 | P8: Delayed | Q8: 56
A9: FL007 | B9: 2024-08-04 | C9: Spirit | D9: Boston | E9: BOS | F9: Chicago | G9: MDW | H9: 07:30 | I9: 09:28 | J9: 118 | K9: 1238 | L9: 1000.42 | M9: Business | N9: 202 | O9: 118 | P9: On-Time | Q9: 0
A10: FL008 | B10: 2023-10-07 | C10: Southwest | D10: Newark | E10: EWR | F10: Minneapolis | G10: MSP | H10: 20:45 | I10: 23:28 | J10: 163 | K10: 1384 | L10: 236.39 | M10: First Class | N10: 243 | O10: 187 | P10: On-Time | Q10: 0
A11: FL009 | B11: 2024-05-27 | C11: spirit | D11: San Francisco | E11: SFO | F11: Denver | G11: DEN | H11: 04:45 | I11: 07:01 | J11: 136 | K11: 492 | L11: 1044.44 | M11: Economy | N11: 260 | O11: 90 | P11: Delayed | Q11: 123
A12: FL010 | B12: 2022-05-11 | C12: Spirit | D12: Minneapolis | E12: MSP | F12: Newark | G12: EWR | H12: 16:30 | I12: 22:43 | J12: 373 | K12: 347 | M12: Economy | N12: 274 | O12: 187 | P12: Delayed | Q12: 179
A13: FL011 | B13: 2023-11-28 | C13: United | D13: Las Vegas | E13: LAS | F13: Charlotte | G13: CLT | H13: 05:45 | I13: 07:16 | J13: 91 | K13: 1378 | L13: 1168.51 | M13: Economy | N13: 229 | O13: 77 | P13: Delayed | Q13: 91
A14: FL012 | B14: 2024-11-05 | C14: Southwest | D14: Dallas | E14: DFW | F14: Minneapolis | G14: MSP | H14: 05:00 | I14: 11:36 | J14: 396 | K14: 1627 | L14: 627.24 | M14: Economy | N14: 337 | O14: 235 | P14: Delayed | Q14: 93
A15: FL013 | B15: 2023-05-06 | C15: Delta | D15: Denver | E15: DEN | F15: San Diego | G15: SAN | H15: 02:00 | I15: 09:44 | J15: 464 | K15: 2290 | L15: 993.95 | M15: First Class | N15: 296 | O15: 82 | P15: On-Time | Q15: 0
A16: FL014 | B16: 2024-08-31 | C16: American | D16: Boston | E16: BOS | F16: Orlando | G16: MCO | H16: 19:45 | I16: 23:03 | J16: 198 | K16: 2508 | L16: 925.9 | M16: First Class | N16: 151 | O16: 141 | P16: On-Time | Q16: 0
A17: FL015 | B17: 2024-02-04 | C17: Frontier | D17: Houston | E17: IAH | F17: Charlotte | G17: CLT | H17: 03:15 | I17: 06:40 | J17: 205 | K17: 562 | L17: 458.66 | M17: First Class | N17: 241 | O17: 108 | P17: On-Time | Q17: 0
A18: FL016 | B18: 2022-01-15 | C18: United | D18: Los Angeles | E18: LAX | F18: Boston | G18: BOS | H18: 02:00 | I18: 06:19 | J18: 259 | K18: 590 | L18: 655.85 | M18: Business | N18: 271 | O18: 174 | P18: On-Time | Q18: 0
A19: FL017 | B19: 2022-09-28 | C19: Frontier | D19: Denver | E19: DEN | F19: Houston | G19: IAH | H19: 13:15 | I19: 15:33 | J19: 138 | K19: 697 | L19: 818.06 | M19: Business | N19: 208 | O19: 155 | P19: On-Time | Q19: 0
A20: FL018 | B20: 2022-04-21 | C20: United | D20: Los Angeles | E20: LAX | F20: Detroit | G20: DTW | H20: 23:30 | I20: 01:55 | J20: 145 | K20: 1318 | L20: 294.58 | M20: First Class | N20: 214 | O20: 85 | P20: On-Time | Q20: 0
A21: FL019 | B21: 2023-07-25 | C21: Frontier | D21: Denver | E21: DEN | F21: Chicago | G21: ORD | H21: 14:00 | I21: 15:55 | J21: 115 | K21: 2971 | L21: 1199.2 | M21: Economy | N21: 348 | O21: 97 | P21: Delayed | Q21: 75
A22: FL020 | B22: 2022-12-07 | C22: Spirit | D22: Newark | E22: EWR | F22: Houston | G22: IAH | H22: 06:45 | I22: 08:45 | J22: 120 | K22: 974 | L22: 504.45 | M22: Business | N22: 167 | O22: 150 | P22: Delayed | Q22: 88
A23: FL021 | B23: 2024-05-16 | C23: Frontier | D23: Dallas | E23: DFW | F23: Denver | G23: DEN | H23: 09:15 | I23: 11:14 | J23: 119 | K23: 2672 | L23: 904.03 | M23: Economy | N23: 291 | O23: 130 | P23: On-Time | Q23: 0
A24: FL022 | B24: 2024-09-03 | C24: American | D24: Los Angeles | E24: LAX | F24: Orlando | G24: MCO | H24: 02:15 | I24: 04:20 | J24: 125 | K24: 2737 | L24: 156.12 | M24: Economy | N24: 203 | O24: 80 | P24: Cancelled | Q24: 0
... A29: FL027 | B29: 2023-06-25 | C29: Frontier | D29: Boston | E29: BOS | F29: Los Angeles | G29: LAX | H29: 02:45 | I29: 06:36 | J29: 231 | K29: 480 | L29: 83.97 | M29: Economy | N29: 263 | O29: 117 | P29: On-Time | Q29: 0
A30: FL028 | B30: 2024-06-23 | C30: Spirit | D30: Orlando | E30: MCO | F30: New York | G30: JFK | H30: 03:00 | I30: 10:23 | J30: 443 | K30: 910 | L30: 691.06 | M30: Business | N30: 249 | P30: On-Time | Q30: 0
A31: FL029 | B31: 2022-09-19 | C31: Delta | D31: Las Vegas | E31: LAS | F31: Minneapolis | G31: MSP | H31: 01:30 | I31: 04:47 | J31: 197 | K31: 1322 | L31: 826.97 | M31: Business | N31: 299 | O31: 193 | P31: Delayed | Q31: 119
A32: FL030 | B32: 2022-11-13 | C32: Southwest | D32: Miami | E32: MIA | F32: Seattle | G32: SEA | H32: 13:00 | I32: 16:01 | J32: 181 | K32: 1660 | L32: 956.27 | M32: Business | N32: 305 | O32: 177 | P32: On-Time | Q32: 0
A33: FL031 | B33: 2022-08-10 | C33: Spirit | D33: Los Angeles | E33: LAX | F33: Houston | G33: IAH | H33: 07:15 | I33: 12:40 | J33: 325 | K33: 1732 | M33: Economy | N33: 157 | O33: 53 | P33: Delayed | Q33: 117
A34: FL032 | B34: 2023-11-04 | C34: JetBlue | D34: Chicago | E34: ORD | F34: Las Vegas | G34: LAS | H34: 11:45 | I34: 19:02 | J34: 437 | K34: 2496 | L34: 450.89 | M34: Economy | N34: 129 | O34: 83 | P34: On-Time | Q34: 0
A35: FL033 | B35: 2023-06-28 | C35: Delta | D35: Atlanta | E35: ATL | F35: Charlotte | G35: CLT | H35: 11:30 | I35: 16:43 | J35: 313 | K35: 2783 | L35: 1182.34 | M35: Economy | N35: 198 | O35: 197 | P35: On-Time | Q35: 0
A36: FL034 | B36: 2022-04-01 | C36: Spirit | D36: New York | E36: JFK | F36: Orlando | G36: MCO | H36: 17:15 | I36: 21:51 | J36: 276 | K36: 2066 | L36: 158.37 | M36: First Class | N36: 335 | O36: 219 | P36: On-Time | Q36: -10
A37: FL035 | B37: 2022-09-13 | C37: JetBlue | D37: Houston | E37: IAH | F37: Las Vegas | G37: LAS | H37: 21:45 | I37: 02:02 | J37: 257 | K37: 1948 | L37: 860.87 | M37: First Class | N37: 132 | O37: 74 | P37: On-Time | Q37: 0
A38: FL036 | B38: 2024-02-16 | C38: American | D38: San Diego | E38: SAN | F38: Chicago | G38: MDW | H38: 09:45 | I38: 15:55 | J38: 370 | K38: 301 | L38: 420.34 | M38: Economy | N38: 210 | O38: 198 | P38: On-Time | Q38: 0
A39: FL037 | B39: 2023-10-22 | C39: Frontier | D39: Charlotte | E39: CLT | F39: Newark | G39: EWR | H39: 21:15 | I39: 03:06 | J39: 351 | K39: 2238 | L39: 968.98 | M39: First Class | N39: 143 | O39: 134 | P39: On-Time | Q39: 0
A40: FL038 | B40: 2024-11-21 | C40: Alaska | D40: Chicago | E40: ORD | F40: Boston | G40: BOS | H40: 21:30 | I40: 00:55 | J40: 205 | K40: 1115 | L40: 245.04 | M40: Economy | N40: 162 | O40: 110 | P40: On-Time | Q40: 0
A41: FL039 | B41: 2022-05-30 | C41: Frontier | D41: Detroit | E41: DTW | F41: San Diego | G41: SAN | H41: 06:45 | I41: 12:28 | J41: 343 | K41: 1936 | L41: 353.26 | M41: First Class | N41: 276 | O41: 51 | P41: Delayed | Q41: 42
A42: FL040 | B42: 2024-05-20 | C42: Southwest | D42: Miami | E42: MIA | F42: Orlando | G42: MCO | H42: 14:00 | I42: 20:15 | J42: 375 | K42: 1320 | L42: 1107.57 | M42: Economy | N42: 216 | O42: 84 | P42: Delayed | Q42: 150
A43: FL041 | B43: 2023-10-12 | C43: Frontier | D43: San Diego | E43: SAN | F43: Houston | G43: IAH | H43: 13:45 | I43: 16:36 | J43: 171 | K43: 2244 | L43: 584.08 | M43: Economy | N43: 315 | O43: 191 | P43: Delayed | Q43: 148
A44: FL042 | B44: 2024-09-19 | C44: Southwest | D44: Boston | E44: BOS | F44: Newark | G44: EWR | H44: 02:30 | I44: 06:00 | J44: 210 | K44: 1412 | L44: 456.15 | M44: First Class | N44: 120 | O44: 67 | P44: On-Time | Q44: 0
...

Sheet ✈ Flights (2)
A1: Flight Id | B1: Flight Date | C1: Airline | D1: Origin City | E1: Origin Code | F1: Destination City | G1: Routes | H1: Destination Code | I1: Departure Time | J1: Arrival Time | K1: Flight Duration Min | L1: Distance Miles | M1: Ticket Price | N1: Class | O1: Seats Available | P1: Passengers Boarded | Q1: Occupancy Rate. | R1: Status | S1: Year-MONTH | T1: Delay Minutes
A2: FL001 | B2: 44790 | C2: Delta | D2: Boston | E2: BOS | F2: Denver | G2: =D2&" → "&F2 -> Boston → Denver | H2: DEN | I2: 07:15 | J2: 15:02 | K2: 467 | L2: 719 | M2: 837.9 | N2: First Class | O2: 122 | P2: 104 | Q2: =P2/O2*100 -> 85.245902 | R2: On-Time | S2: =TEXT(B2,"YYYY-MM") -> 2022-08 | T2: 0
A3: FL002 | B3: 44753 | C3: Southwest | D3: Denver | E3: DEN | F3: Orlando | G3: =D3&" → "&F3 -> Denver → Orlando | H3: MCO | I3: 19:00 | J3: 01:17 | K3: 377 | L3: 1114 | M3: 881.94 | N3: First Class | O3: 239 | P3: 157 | Q3: =P3/O3*100 -> 65.690377 | R3: On-Time | S3: =TEXT(B3,"YYYY-MM") -> 2022-07 | T3: 0
A4: FL003 | B4: 45131 | C4: Delta | D4: Miami | E4: MIA | F4: Charlotte | G4: =D4&" → "&F4 -> Miami → Charlotte | H4: CLT | I4: 10:30 | J4: 13:19 | K4: 169 | L4: 1181 | M4: 1152.08 | N4: Business | O4: 126 | P4: 61 | Q4: =P4/O4*100 -> 48.412698 | R4: On-Time | S4: =TEXT(B4,"YYYY-MM") -> 2023-07 | T4: 0
A5: FL004 | B5: 45297 | C5: Alaska | D5: San Diego | E5: SAN | F5: Boston | G5: =D5&" → "&F5 -> San Diego → Boston | H5: BOS | I5: 01:45 | J5: 07:49 | K5: 364 | L5: 811 | M5: 1169.89 | N5: Business | O5: 120 | P5: 120 | Q5: =P5/O5*100 -> 100 | R5: On-Time | S5: =TEXT(B5,"YYYY-MM") -> 2024-01 | T5: 0
A6: FL005 | B6: 45302 | C6: Southwest | D6: Chicago | E6: ORD | F6: Los Angeles | G6: =D6&" → "&F6 -> Chicago → Los Angeles | H6: LAX | I6: 21:15 | J6: 01:13 | K6: 238 | L6: 626 | M6: 1037.96 | N6: Economy | O6: 197 | P6: 121 | Q6: =P6/O6*100 -> 61.42132 | R6: On-Time | S6: =TEXT(B6,"YYYY-MM") -> 2024-01 | T6: 0
A7: FL006 | B7: 45309 | C7: American | D7: San Francisco | E7: SFO | F7: Minneapolis | G7: =D7&" → "&F7 -> San Francisco → Minneapolis | H7: MSP | I7: 06:30 | J7: 13:59 | K7: 449 | L7: 2954 | M7: 159.97 | N7: First Class | O7: 143 | P7: 118 | Q7: =P7/O7*100 -> 82.517483 | R7: Delayed | S7: =TEXT(B7,"YYYY-MM") -> 2024-01 | T7: 56 | Z7: Origin Code | AA7: Count of Flight Id
A8: FL007 | B8: 45508 | C8: Spirit | D8: Boston | E8: BOS | F8: Chicago | G8: =D8&" → "&F8 -> Boston → Chicago | H8: MDW | I8: 07:30 | J8: 09:28 | K8: 118 | L8: 1238 | M8: 1000.42 | N8: Business | O8: 202 | P8: 118 | Q8: =P8/O8*100 -> 58.415842 | R8: On-Time | S8: =TEXT(B8,"YYYY-MM") -> 2024-08 | T8: 0 | Z8: ATL | AA8: 33
A9: FL008 | B9: 45206 | C9: Southwest | D9: Newark | E9: EWR | F9: Minneapolis | G9: =D9&" → "&F9 -> Newark → Minneapolis | H9: MSP | I9: 20:45 | J9: 23:28 | K9: 163 | L9: 1384 | M9: 236.39 | N9: First Class | O9: 243 | P9: 187 | Q9: =P9/O9*100 -> 76.954733 | R9: On-Time | S9: =TEXT(B9,"YYYY-MM") -> 2023-10 | T9: 0 | Z9: LAX | AA9: 32
A10: FL009 | B10: 45439 | C10: Spirit | D10: San Francisco | E10: SFO | F10: Denver | G10: =D10&" → "&F10 -> San Francisco → Denver | H10: DEN | I10: 04:45 | J10: 07:01 | K10: 136 | L10: 492 | M10: 1044.44 | N10: Economy | O10: 260 | P10: 90 | Q10: =P10/O10*100 -> 34.615385 | R10: Delayed | S10: =TEXT(B10,"YYYY-MM") -> 2024-05 | T10: 123 | Z10: SAN | AA10: 30
A11: FL010 | B11: 44692 | C11: Spirit | D11: Minneapolis | E11: MSP | F11: Newark | G11: =D11&" → "&F11 -> Minneapolis → Newark | H11: EWR | I11: 16:30 | J11: 22:43 | K11: 373 | L11: 347 | M11: 587.19 | N11: Economy | O11: 274 | P11: 187 | Q11: =P11/O11*100 -> 68.248175 | R11: Delayed | S11: =TEXT(B11,"YYYY-MM") -> 2022-05 | T11: 179 | Z11: SFO | AA11: 28
A12: FL011 | B12: 45258 | C12: United | D12: Las Vegas | E12: LAS | F12: Charlotte | G12: =D12&" → "&F12 -> Las Vegas → Charlotte | H12: CLT | I12: 05:45 | J12: 07:16 | K12: 91 | L12: 1378 | M12: 587.19 | N12: Economy | O12: 229 | P12: 77 | Q12: =P12/O12*100 -> 33.624454 | R12: Delayed | S12: =TEXT(B12,"YYYY-MM") -> 2023-11 | T12: 91 | Z12: MSP | AA12: 27
A13: FL012 | B13: 45601 | C13: Southwest | D13: Dallas | E13: DFW | F13: Minneapolis | G13: =D13&" → "&F13 -> Dallas → Minneapolis | H13: MSP | I13: 05:00 | J13: 11:36 | K13: 396 | L13: 1627 | M13: 494.955 | N13: Economy | O13: 337 | P13: 235 | Q13: =P13/O13*100 -> 69.732938 | R13: Delayed | S13: =TEXT(B13,"YYYY-MM") -> 2024-11 | T13: 93 | Z13: CLT | AA13: 27
A14: FL013 | B14: 45052 | C14: Delta | D14: Denver | E14: DEN | F14: San Diego | G14: =D14&" → "&F14 -> Denver → San Diego | H14: SAN | I14: 02:00 | J14: 09:44 | K14: 464 | L14: 2290 | M14: 587.19 | N14: First Class | O14: 296 | P14: 82 | Q14: =P14/O14*100 -> 27.702703 | R14: On-Time | S14: =TEXT(B14,"YYYY-MM") -> 2023-05 | T14: 0 | Z14: JFK | AA14: 26
A15: FL014 | B15: 45535 | C15: American | D15: Boston | E15: BOS | F15: Orlando | G15: =D15&" → "&F15 -> Boston → Orlando | H15: MCO | I15: 19:45 | J15: 23:03 | K15: 198 | L15: 2508 | M15: 677.705 | N15: First Class | O15: 151 | P15: 141 | Q15: =P15/O15*100 -> 93.377483 | R15: On-Time | S15: =TEXT(B15,"YYYY-MM") -> 2024-08 | T15: 0 | Z15: DTW | AA15: 26
A16: FL015 | B16: 45326 | C16: Frontier | D16: Houston | E16: IAH | F16: Charlotte | G16: =D16&" → "&F16 -> Houston → Charlotte | H16: CLT | I16: 03:15 | J16: 06:40 | K16: 205 | L16: 562 | M16: 579.745 | N16: First Class | O16: 241 | P16: 108 | Q16: =P16/O16*100 -> 44.813278 | R16: On-Time | S16: =TEXT(B16,"YYYY-MM") -> 2024-02 | T16: 0 | Z16: BOS | AA16: 26
A17: FL016 | B17: 44576 | C17: United | D17: Los Angeles | E17: LAX | F17: Boston | G17: =D17&" → "&F17 -> Los Angeles → Boston | H17: BOS | I17: 02:00 | J17: 06:19 | K17: 259 | L17: 590 | M17: 498.48 | N17: Business | O17: 271 | P17: 174 | Q17: =P17/O17*100 -> 64.206642 | R17: On-Time | S17: =TEXT(B17,"YYYY-MM") -> 2022-01 | T17: 0 | Z17: PHX | AA17: 25
A18: FL017 | B18: 44832 | C18: Frontier | D18: Denver | E18: DEN | F18: Houston | G18: =D18&" → "&F18 -> Denver → Houston | H18: IAH | I18: 13:15 | J18: 15:33 | K18: 138 | L18: 697 | M18: 527.085 | N18: Business | O18: 208 | P18: 155 | Q18: =P18/O18*100 -> 74.519231 | R18: On-Time | S18: =TEXT(B18,"YYYY-MM") -> 2022-09 | T18: 0 | Z18: MDW | AA18: 25
A19: FL018 | B19: 44672 | C19: United | D19: Los Angeles | E19: LAX | F19: Detroit | G19: =D19&" → "&F19 -> Los Angeles → Detroit | H19: DTW | I19: 23:30 | J19: 01:55 | K19: 145 | L19: 1318 | M19: 627.39 | N19: First Class | O19: 214 | P19: 85 | Q19: =P19/O19*100 -> 39.719626 | R19: On-Time | S19: =TEXT(B19,"YYYY-MM") -> 2022-04 | T19: 0 | Z19: ORD | AA19: 24
... A28: FL027 | B28: 45102 | C28: Frontier | D28: Boston | E28: BOS | F28: Los Angeles | G28: =D28&" → "&F28 -> Boston → Los Angeles | H28: LAX | I28: 02:45 | J28: 06:36 | K28: 231 | L28: 480 | M28: 498.48 | N28: Economy | O28: 263 | P28: 117 | Q28: =P28/O28*100 -> 44.486692 | R28: On-Time | S28: =TEXT(B28,"YYYY-MM") -> 2023-06 | T28: 0 | Z28: Grand Total | AA28: 500
A29: FL028 | B29: 45466 | C29: Spirit | D29: Orlando | E29: MCO | F29: New York | G29: =D29&" → "&F29 -> Orlando → New York | H29: JFK | I29: 03:00 | J29: 10:23 | K29: 443 | L29: 910 | M29: 587.19 | N29: Business | O29: 249 | P29: 142 | Q29: =P29/O29*100 -> 57.028112 | R29: On-Time | S29: =TEXT(B29,"YYYY-MM") -> 2024-06 | T29: 0
A30: FL029 | B30: 44823 | C30: Delta | D30: Las Vegas | E30: LAS | F30: Minneapolis | G30: =D30&" → "&F30 -> Las Vegas → Minneapolis | H30: MSP | I30: 01:30 | J30: 04:47 | K30: 197 | L30: 1322 | M30: 527.085 | N30: Business | O30: 299 | P30: 193 | Q30: =P30/O30*100 -> 64.548495 | R30: Delayed | S30: =TEXT(B30,"YYYY-MM") -> 2022-09 | T30: 119
A31: FL030 | B31: 44878 | C31: Southwest | D31: Miami | E31: MIA | F31: Seattle | G31: =D31&" → "&F31 -> Miami → Seattle | H31: SEA | I31: 13:00 | J31: 16:01 | K31: 181 | L31: 1660 | M31: 956.27 | N31: Business | O31: 305 | P31: 177 | Q31: =P31/O31*100 -> 58.032787 | R31: On-Time | S31: =TEXT(B31,"YYYY-MM") -> 2022-11 | T31: 0
A32: FL031 | B32: 44783 | C32: Spirit | D32: Los Angeles | E32: LAX | F32: Houston | G32: =D32&" → "&F32 -> Los Angeles → Houston | H32: IAH | I32: 07:15 | J32: 12:40 | K32: 325 | L32: 1732 | M32: 587.19 | N32: Economy | O32: 157 | P32: 53 | Q32: =P32/O32*100 -> 33.757962 | R32: Delayed | S32: =TEXT(B32,"YYYY-MM") -> 2022-08 | T32: 117
A33: FL032 | B33: 45234 | C33: Jetblue | D33: Chicago | E33: ORD | F33: Las Vegas | G33: =D33&" → "&F33 -> Chicago → Las Vegas | H33: LAS | I33: 11:45 | J33: 19:02 | K33: 437 | L33: 2496 | M33: 450.89 | N33: Economy | O33: 129 | P33: 83 | Q33: =P33/O33*100 -> 64.341085 | R33: On-Time | S33: =TEXT(B33,"YYYY-MM") -> 2023-11 | T33: 0
A34: FL033 | B34: 45105 | C34: Delta | D34: Atlanta | E34: ATL | F34: Charlotte | G34: =D34&" → "&F34 -> Atlanta → Charlotte | H34: CLT | I34: 11:30 | J34: 16:43 | K34: 313 | L34: 2783 | M34: 1182.34 | N34: Economy | O34: 198 | P34: 197 | Q34: =P34/O34*100 -> 99.494949 | R34: On-Time | S34: =TEXT(B34,"YYYY-MM") -> 2023-06 | T34: 0
A35: FL034 | B35: 44652 | C35: Spirit | D35: New York | E35: JFK | F35: Orlando | G35: =D35&" → "&F35 -> New York → Orlando | H35: MCO | I35: 17:15 | J35: 21:51 | K35: 276 | L35: 2066 | M35: 158.37 | N35: First Class | O35: 335 | P35: 219 | Q35: =P35/O35*100 -> 65.373134 | R35: On-Time | S35: =TEXT(B35,"YYYY-MM") -> 2022-04 | T35: 0
A36: FL035 | B36: 44817 | C36: Jetblue | D36: Houston | E36: IAH | F36: Las Vegas | G36: =D36&" → "&F36 -> Houston → Las Vegas | H36: LAS | I36: 21:45 | J36: 02:02 | K36: 257 | L36: 1948 | M36: 860.87 | N36: First Class | O36: 132 | P36: 74 | Q36: =P36/O36*100 -> 56.060606 | R36: On-Time | S36: =TEXT(B36,"YYYY-MM") -> 2022-09 | T36: 0
A37: FL036 | B37: 45338 | C37: American | D37: San Diego | E37: SAN | F37: Chicago | G37: =D37&" → "&F37 -> San Diego → Chicago | H37: MDW | I37: 09:45 | J37: 15:55 | K37: 370 | L37: 301 | M37: 420.34 | N37: Economy | O37: 210 | P37: 198 | Q37: =P37/O37*100 -> 94.285714 | R37: On-Time | S37: =TEXT(B37,"YYYY-MM") -> 2024-02 | T37: 0
A38: FL037 | B38: 45221 | C38: Frontier | D38: Charlotte | E38: CLT | F38: Newark | G38: =D38&" → "&F38 -> Charlotte → Newark | H38: EWR | I38: 21:15 | J38: 03:06 | K38: 351 | L38: 2238 | M38: 968.98 | N38: First Class | O38: 143 | P38: 134 | Q38: =P38/O38*100 -> 93.706294 | R38: On-Time | S38: =TEXT(B38,"YYYY-MM") -> 2023-10 | T38: 0
A39: FL038 | B39: 45617 | C39: Alaska | D39: Chicago | E39: ORD | F39: Boston | G39: =D39&" → "&F39 -> Chicago → Boston | H39: BOS | I39: 21:30 | J39: 00:55 | K39: 205 | L39: 1115 | M39: 245.04 | N39: Economy | O39: 162 | P39: 110 | Q39: =P39/O39*100 -> 67.901235 | R39: On-Time | S39: =TEXT(B39,"YYYY-MM") -> 2024-11 | T39: 0
A40: FL039 | B40: 44711 | C40: Frontier | D40: Detroit | E40: DTW | F40: San Diego | G40: =D40&" → "&F40 -> Detroit → San Diego | H40: SAN | I40: 06:45 | J40: 12:28 | K40: 343 | L40: 1936 | M40: 353.26 | N40: First Class | O40: 276 | P40: 51 | Q40: =P40/O40*100 -> 18.478261 | R40: Delayed | S40: =TEXT(B40,"YYYY-MM") -> 2022-05 | T40: 42
... A501: FL500 | B501: 45506 | C501: Spirit | D501: Chicago | E501: MDW | F501: Seattle | G501: =D501&" → "&F501 -> Chicago → Seattle | H501: SEA | I501: 16:30 | J501: 23:46 | K501: 436 | L501: 1036 | M501: 430.86 | N501: Economy | O501: 272 | P501: 52 | Q501: =P501/O501*100 -> 19.117647 | R501: Delayed | S501: =TEXT(B501,"YYYY-MM") -> 2024-08 | T501: 18

Sheet 🏢 Airports
A1: 🏢 AIRPORTS REFERENCE TABLE
A2: Airport Code | B2: Airport Name | C2: City | D2: Country | E2: Terminals | F2: Annual Capacity
A3: JFK | B3: John F. Kennedy International | C3: New York | D3: USA | E3: 8 | F3: 62000000
A4: LAX | B4: Los Angeles International | C4: Los Angeles | D4: USA | E4: 9 | F4: 88000000
A5: ORD | B5: O'Hare International | C5: Chicago | D5: USA | E5: 4 | F5: 54000000
A6: ATL | B6: Hartsfield-Jackson Atlanta | C6: Atlanta | D6: USA | E6: 2 | F6: 107000000
A7: DFW | B7: Dallas/Fort Worth International | C7: Dallas | D7: USA | E7: 5 | F7: 73000000
A8: MIA | B8: Miami International | C8: Miami | D8: USA | E8: 3 | F8: 45000000
A9: SEA | B9: Seattle-Tacoma International | C9: Seattle | D9: USA | E9: 3 | F9: 51000000
A10: DEN | B10: Denver International | C10: Denver | D10: USA | E10: 3 | F10: 69000000
A11: BOS | B11: Logan International | C11: Boston | D11: USA | E11: 4 | F11: 40000000
A12: LAS | B12: Harry Reid International | C12: Las Vegas | D12: USA | E12: 2 | F12: 51000000
A13: PHX | B13: Phoenix Sky Harbor | C13: Phoenix | D13: USA | E13: 3 | F13: 46000000
A14: SFO | B14: San Francisco International | C14: San Francisco | D14: USA | E14: 4 | F14: 57000000
... A22: SAN | B22: San Diego International | C22: San Diego | D22: USA | E22: 2 | F22: 25000000
S510: =VLOOKUP(B2,Flights!$A$2:$P$508,12,0)'

Sheet 💰 Revenue
A1: 💰 REVENUE & COSTS TABLE (Contains Dirty Data)
A2: Revenue Id | B2: Flight Id | C2: Airport Code | D2: Total Revenue | E2: Ancillary Revenue | F2: Fuel Cost | G2: Crew Cost | H2: Profit | I2: Payment Method
A3: REV001 | B3: FL001 | C3: BOS | D3: 87141.6 | E3: 1232.74 | F3: 8636.75 | G3: 7797.25 | H3: 71940.34 | I3: Cash
A4: REV002 | B4: FL002 | C4: DEN | D4: 138464.58 | E4: 5939.38 | F4: 13816.36 | G4: 2442.54 | H4: 128145.06 | I4: Credit Card
A5: REV003 | B5: FL003 | C5: MIA | D5: 70276.88 | E5: 926.61 | F5: 25794.85 | G5: 13621.57 | H5: 31787.07 | I5: Cash
A6: REV004 | B6: FL004 | C6: SAN | D6: 140386.8 | E6: 7628.67 | F6: 27332.9 | G6: 11204.98 | H6: 109477.59 | I6: Credit Card
A7: REV005 | B7: FL005 | C7: ORD | D7: 125593.16 | E7: 1147.9 | F7: 26164 | G7: 6887.46 | H7: 93689.6 | I7: Cash
A8: REV006 | B8: FL006 | C8: SFO | D8: 18876.46 | E8: 7220.01 | F8: 29347.88 | G8: 5293.36 | H8: -8544.77 | I8: Debit Card
A9: REV007 | B9: FL007 | C9: BOS | D9: 118049.56 | E9: 5453.58 | F9: 7650 | G9: 7894.77 | H9: 107958.37 | I9: Travel Points
A10: REV008 | B10: FL008 | C10: EWR | D10: 44204.93 | E10: 6270.19 | F10: 29227.75 | G10: 10678.53 | H10: 10568.84 | I10: Travel Points
A11: REV009 | B11: FL009 | C11: SFO | D11: 93999.6 | E11: 2430.02 | F11: 32325.6 | G11: 5604.74 | H11: 58499.28 | I11: Credit Card
A12: REV010 | B12: FL010 | C12: MSP | D12: 157439.04 | E12: 3370.99 | F12: 16642.92 | G12: 2780.76 | H12: 141386.35 | I12: Travel Points
A13: REV011 | B13: FL011 | C13: LAS | D13: 89975.27 | E13: 1834.47 | F13: 7428.95 | G13: 14732.49 | H13: 69648.3 | I13: Cash
A14: REV012 | B14: FL012 | C14: DFW | D14: 147401.4 | E14: 5077.26 | F14: 11245.48 | G14: 8396.74 | H14: 132836.44 | I14: Cash
... A63: REV061 | B63: FL061 | C63: DFW | D63: 142418.08 | E63: 7213.09 | F63: 30249.11 | G63: 9705.19 | H63: 109676.87 | I63: Travel Points
A64: REV062 | B64: FL062 | C64: CLT | D64: 0 | E64: 0 | G64: 11712.13 | H64: -31379.45 | I64: Travel Points
A65: REV063 | B65: FL063 | C65: BOS | D65: 27071.55 | E65: 2225.47 | F65: 8854.65 | G65: 4961.17 | H65: 15481.2 | I65: Cash
A66: REV064 | B66: FL064 | C66: DEN | D66: 29548.2 | E66: 6033.11 | F66: 35446.02 | G66: 6881.92 | H66: -6746.63 | I66: Cash
A67: REV065 | B67: FL065 | C67: ATL | D67: 20477.44 | E67: 1051.47 | F67: 25478.23 | G67: 2706.41 | H67: -6655.73 | I67: Debit Card
A68: REV066 | B68: FL066 | C68: ATL | D68: 199900.8 | E68: 1587.06 | F68: 37476.05 | G68: 7914.88 | H68: 156096.93 | I68: Debit Card
A69: REV067 | B69: FL067 | C69: PHX | D69: 163742.76 | E69: 3301.14 | F69: 21020.91 | G69: 4524.01 | H69: 141498.98 | I69: Travel Points
A70: REV068 | B70: FL068 | C70: EWR | D70: 308717.64 | E70: 7816.67 | F70: 12077.38 | G70: 3653.75 | H70: 300803.18 | I70: Credit Card
A71: REV069 | B71: FL069 | C71: SFO | D71: 183156.16 | E71: 2604.53 | F71: 8888.82 | G71: 8051.95 | H71: 168819.92 | I71: Debit Card
A72: REV070 | B72: FL070 | C72: CLT | D72: 365148.93 | E72: 1784.01 | F72: 17025.16 | G72: 13523.32 | H72: 336384.46 | I72: Cash
A73: REV071 | B73: FL071 | C73: LAX | D73: 65558.64 | E73: 6421.6 | F73: 27329.97 | G73: 9949.87 | H73: 34700.4 | I73: Cash
A74: REV072 | B74: FL072 | C74: EWR | D74: 65918.16 | E74: 4835.91 | F74: 24346.45 | G74: 4986.13 | H74: 41421.49 | I74: Debit Card
A75: REV073 | B75: FL073 | C75: ATL | D75: 158696.85 | E75: 6927.3 | F75: 22122.47 | G75: 14943.64 | H75: 128558.04 | I75: Debit Card
A76: REV074 | B76: FL074 | C76: SEA | D76: 169226.6 | E76: 6777.42 | F76: 14770.98 | G76: 11490.23 | H76: 149742.81 | I76: Cash
... A93: REV091 | B93: FL091 | C93: DTW | D93: 0 | E93: 0 | F93: 17825.15 | G93: 10426.24 | H93: -28251.39 | I93: Credit Card
A94: REV092 | B94: FL092 | C94: SFO | D94: 109695.18 | E94: 4705.69 | G94: 3799.28 | H94: 78526.45 | I94: Travel Points
A95: REV093 | B95: FL093 | C95: LAX | D95: 19605 | E95: 2289.75 | F95: 8974.52 | G95: 8220.42 | H95: 4699.81 | I95: Cash
A96: REV094 | B96: FL094 | C96: DFW | D96: 19118.69 | E96: 6148.8 | F96: 31631.01 | G96: 6166.03 | H96: -12529.55 | I96: Travel Points
A97: REV095 | B97: FL095 | C97: MDW | D97: 17535.63 | E97: 4276.74 | F97: 19802.52 | G97: 2707.98 | H97: -698.13 | I97: Travel Points
A98: REV096 | B98: FL096 | C98: IAH | D98: 284717.5 | E98: 3089.2 | F98: 22017.94 | G98: 8846.87 | H98: 256941.89 | I98: Credit Card
A99: REV097 | B99: FL097 | C99: JFK | D99: 37746 | E99: 4026.23 | F99: 23616.66 | G99: 12729.93 | H99: 5425.64 | I99: Travel Points
A100: REV098 | B100: FL098 | C100: DFW | D100: 137540.88 | E100: 3889.84 | F100: 17885.1 | G100: 10752.98 | H100: 112792.64 | I100: Credit Card
A101: REV099 | B101: FL099 | C101: DTW | D101: 47392.2 | E101: 1912.65 | F101: 35939.26 | G101: 3135.01 | H101: 10230.58 | I101: Debit Card
A102: REV100 | B102: FL100 | C102: DFW | D102: 81736.5 | E102: 7234.59 | F102: 15093.04 | G102: 14436.15 | H102: 59441.9 | I102: Credit Card
A103: REV101 | B103: FL101 | C103: ATL | D103: 163045.4 | E103: 1735.75 | F103: 8920.86 | G103: 3923.4 | H103: 151936.89 | I103: Cash
A104: REV102 | B104: FL102 | C104: DFW | D104: 52608.69 | E104: 7062.45 | F104: 23224.07 | G104: 10154.59 | H104: 26292.48 | I104: Travel Points
...

Sheet 💰 Revenue (2)
A1: Revenue Id | B1: Flight Id | C1: Airport Code | D1: Airline | E1: Total Revenue | F1: Revenue Per Mile | G1: Ancillary Revenue | H1: Crew Cost | I1: Fuel Cost2 | J1: Profit | K1: Payment Method | L1: Ticket price | M1: Passenger Boarded | N1: Class | O1: Distance Mile
A2: REV001 | B2: FL001 | C2: BOS | D2: =VLOOKUP(B2,'✈ Flights (2)'!$A$2:$P$502,3,FALSE) -> Delta | E2: 87141.6 | F2: =E2/O2 -> 121.19833 | G2: 1232.74 | H2: 7797.25 | I2: 8636.75 | J2: 71940.34 | K2: Cash | L2: =VLOOKUP(B2,'✈ Flights (2)'!$A$2:$R$501,13,FALSE) -> 837.9 | M2: =VLOOKUP(B2,'✈ Flights (2)'!$A$2:$R$501,16,FALSE) -> 104 | N2: =VLOOKUP(B2,'✈ Flights (2)'!$A$2:$R$501,14,FALSE) -> First Class | O2: =VLOOKUP(B2,'✈ Flights (2)'!$A$2:$P$502,12,FALSE) -> 719
A3: REV002 | B3: FL002 | C3: DEN | D3: =VLOOKUP(B3,'✈ Flights (2)'!$A$2:$P$502,3,FALSE) -> Southwest | E3: 138464.58 | F3: =E3/O3 -> 124.29496 | G3: 5939.38 | H3: 2442.54 | I3: 13816.36 | J3: 128145.06 | K3: Credit Card | L3: =VLOOKUP(B3,'✈ Flights (2)'!$A$2:$R$501,13,FALSE) -> 881.94 | M3: =VLOOKUP(B3,'✈ Flights (2)'!$A$2:$R$501,16,FALSE) -> 157 | N3: =VLOOKUP(B3,'✈ Flights (2)'!$A$2:$R$501,14,FALSE) -> First Class | O3: =VLOOKUP(B3,'✈ Flights (2)'!$A$2:$P$502,12,FALSE) -> 1114
A4: REV003 | B4: FL003 | C4: MIA | D4: =VLOOKUP(B4,'✈ Flights (2)'!$A$2:$P$502,3,FALSE) -> Delta | E4: 70276.88 | F4: =E4/O4 -> 59.506249 | G4: 926.61 | H4: 13621.57 | I4: 25794.85 | J4: 31787.07 | K4: Cash | L4: =VLOOKUP(B4,'✈ Flights (2)'!$A$2:$R$501,13,FALSE) -> 1152.08 | M4: =VLOOKUP(B4,'✈ Flights (2)'!$A$2:$R$501,16,FALSE) -> 61 | N4: =VLOOKUP(B4,'✈ Flights (2)'!$A$2:$R$501,14,FALSE) -> Business | O4: =VLOOKUP(B4,'✈ Flights (2)'!$A$2:$P$502,12,FALSE) -> 1181
A5: REV004 | B5: FL004 | C5: SAN | D5: =VLOOKUP(B5,'✈ Flights (2)'!$A$2:$P$502,3,FALSE) -> Alaska | E5: 140386.8 | F5: =E5/O5 -> 173.10333 | G5: 7628.67 | H5: 11204.98 | I5: 27332.9 | J5: 109477.59 | K5: Credit Card | L5: =VLOOKUP(B5,'✈ Flights (2)'!$A$2:$R$501,13,FALSE) -> 1169.89 | M5: =VLOOKUP(B5,'✈ Flights (2)'!$A$2:$R$501,16,FALSE) -> 120 | N5: =VLOOKUP(B5,'✈ Flights (2)'!$A$2:$R$501,14,FALSE) -> Business | O5: =VLOOKUP(B5,'✈ Flights (2)'!$A$2:$P$502,12,FALSE) -> 811
A6: REV005 | B6: FL005 | C6: ORD | D6: =VLOOKUP(B6,'✈ Flights (2)'!$A$2:$P$502,3,FALSE) -> Southwest | E6: 125593.16 | F6: =E6/O6 -> 200.62805 | G6: 1147.9 | H6: 6887.46 | I6: 26164 | J6: 93689.6 | K6: Cash | L6: =VLOOKUP(B6,'✈ Flights (2)'!$A$2:$R$501,13,FALSE) -> 1037.96 | M6: =VLOOKUP(B6,'✈ Flights (2)'!$A$2:$R$501,16,FALSE) -> 121 | N6: =VLOOKUP(B6,'✈ Flights (2)'!$A$2:$R$501,14,FALSE) -> Economy | O6: =VLOOKUP(B6,'✈ Flights (2)'!$A$2:$P$502,12,FALSE) -> 626
A7: REV006 | B7: FL006 | C7: SFO | D7: =VLOOKUP(B7,'✈ Flights (2)'!$A$2:$P$502,3,FALSE) -> American | E7: 18876.46 | F7: =E7/O7 -> 6.3901354 | G7: 7220.01 | H7: 5293.36 | I7: 29347.88 | J7: -8544.77 | K7: Debit Card | L7: =VLOOKUP(B7,'✈ Flights (2)'!$A$2:$R$501,13,FALSE) -> 159.97 | M7: =VLOOKUP(B7,'✈ Flights (2)'!$A$2:$R$501,16,FALSE) -> 118 | N7: =VLOOKUP(B7,'✈ Flights (2)'!$A$2:$R$501,14,FALSE) -> First Class | O7: =VLOOKUP(B7,'✈ Flights (2)'!$A$2:$P$502,12,FALSE) -> 2954
A8: REV007 | B8: FL007 | C8: BOS | D8: =VLOOKUP(B8,'✈ Flights (2)'!$A$2:$P$502,3,FALSE) -> Spirit | E8: 118049.56 | F8: =E8/O8 -> 95.355057 | G8: 5453.58 | H8: 7894.77 | I8: 7650 | J8: 107958.37 | K8: Travel Points | L8: =VLOOKUP(B8,'✈ Flights (2)'!$A$2:$R$501,13,FALSE) -> 1000.42 | M8: =VLOOKUP(B8,'✈ Flights (2)'!$A$2:$R$501,16,FALSE) -> 118 | N8: =VLOOKUP(B8,'✈ Flights (2)'!$A$2:$R$501,14,FALSE) -> Business | O8: =VLOOKUP(B8,'✈ Flights (2)'!$A$2:$P$502,12,FALSE) -> 1238
A9: REV008 | B9: FL008 | C9: EWR | D9: =VLOOKUP(B9,'✈ Flights (2)'!$A$2:$P$502,3,FALSE) -> Southwest | E9: 44204.93 | F9: =E9/O9 -> 31.939978 | G9: 6270.19 | H9: 10678.53 | I9: 29227.75 | J9: 10568.84 | K9: Travel Points | L9: =VLOOKUP(B9,'✈ Flights (2)'!$A$2:$R$501,13,FALSE) -> 236.39 | M9: =VLOOKUP(B9,'✈ Flights (2)'!$A$2:$R$501,16,FALSE) -> 187 | N9: =VLOOKUP(B9,'✈ Flights (2)'!$A$2:$R$501,14,FALSE) -> First Class | O9: =VLOOKUP(B9,'✈ Flights (2)'!$A$2:$P$502,12,FALSE) -> 1384
A10: REV009 | B10: FL009 | C10: SFO | D10: =VLOOKUP(B10,'✈ Flights (2)'!$A$2:$P$502,3,FALSE) -> Spirit | E10: 93999.6 | F10: =E10/O10 -> 191.0561 | G10: 2430.02 | H10: 5604.74 | I10: 32325.6 | J10: 58499.28 | K10: Credit Card | L10: =VLOOKUP(B10,'✈ Flights (2)'!$A$2:$R$501,13,FALSE) -> 1044.44 | M10: =VLOOKUP(B10,'✈ Flights (2)'!$A$2:$R$501,16,FALSE) -> 90 | N10: =VLOOKUP(B10,'✈ Flights (2)'!$A$2:$R$501,14,FALSE) -> Economy | O10: =VLOOKUP(B10,'✈ Flights (2)'!$A$2:$P$502,12,FALSE) -> 492
A11: REV010 | B11: FL010 | C11: MSP | D11: =VLOOKUP(B11,'✈ Flights (2)'!$A$2:$P$502,3,FALSE) -> Spirit | E11: 109804.53 | F11: =E11/O11 -> 316.43957 | G11: 3370.99 | H11: 2780.76 | I11: 16642.92 | J11: 141386.35 | K11: Travel Points | L11: =VLOOKUP(B11,'✈ Flights (2)'!$A$2:$R$501,13,FALSE) -> 587.19 | M11: =VLOOKUP(B11,'✈ Flights (2)'!$A$2:$R$501,16,FALSE) -> 187 | N11: =VLOOKUP(B11,'✈ Flights (2)'!$A$2:$R$501,14,FALSE) -> Economy | O11: =VLOOKUP(B11,'✈ Flights (2)'!$A$2:$P$502,12,FALSE) -> 347
A12: REV011 | B12: FL011 | C12: LAS | D12: =VLOOKUP(B12,'✈ Flights (2)'!$A$2:$P$502,3,FALSE) -> United | E12: 45213.63 | F12: =E12/O12 -> 32.811052 | G12: 1834.47 | H12: 14732.49 | I12: 7428.95 | J12: 69648.3 | K12: Cash | L12: =VLOOKUP(B12,'✈ Flights (2)'!$A$2:$R$501,13,FALSE) -> 587.19 | M12: =VLOOKUP(B12,'✈ Flights (2)'!$A$2:$R$501,16,FALSE) -> 77 | N12: =VLOOKUP(B12,'✈ Flights (2)'!$A$2:$R$501,14,FALSE) -> Economy | O12: =VLOOKUP(B12,'✈ Flights (2)'!$A$2:$P$502,12,FALSE) -> 1378
A13: REV012 | B13: FL012 | C13: DFW | D13: =VLOOKUP(B13,'✈ Flights (2)'!$A$2:$P$502,3,FALSE) -> Southwest | E13: 116314.43 | F13: =E13/O13 -> 71.49012 | G13: 5077.26 | H13: 8396.74 | I13: 11245.48 | J13: 132836.44 | K13: Cash | L13: =VLOOKUP(B13,'✈ Flights (2)'!$A$2:$R$501,13,FALSE) -> 494.955 | M13: =VLOOKUP(B13,'✈ Flights (2)'!$A$2:$R$501,16,FALSE) -> 235 | N13: =VLOOKUP(B13,'✈ Flights (2)'!$A$2:$R$501,14,FALSE) -> Economy | O13: =VLOOKUP(B13,'✈ Flights (2)'!$A$2:$P$502,12,FALSE) -> 1627
... A501: REV500 | B501: FL500 | C501: MDW | D501: =VLOOKUP(B501,'✈ Flights (2)'!$A$2:$P$502,3,FALSE) -> Spirit | E501: 22404.72 | F501: =E501/O501 -> 21.626178 | G501: 3665.46 | H501: 4604.83 | I501: 11839.25 | J501: 9626.1 | K501: Cash | L501: =VLOOKUP(B501,'✈ Flights (2)'!$A$2:$R$501,13,FALSE) -> 430.86 | M501: =VLOOKUP(B501,'✈ Flights (2)'!$A$2:$R$501,16,FALSE) -> 52 | N501: =VLOOKUP(B501,'✈ Flights (2)'!$A$2:$R$501,14,FALSE) -> Economy | O501: =VLOOKUP(B501,'✈ Flights (2)'!$A$2:$P$502,12,FALSE) -> 1036
G504: Average Fuel Cost
U509: =VLOOKUP(B2,Flights!$A$2:$P$508,12,0)'

Sheet 📖 Data Dictionary
A1: 📖 DATA DICTIONARY — AIRLINE DATASET
A2: Table | B2: Column Name | C2: Data Type | D2: Valid Values / Range | E2: Description | F2: Contains Issues? | G2: Key Type | H2: Dirty Data Notes
A3: flights | B3: flight_id | C3: Text | D3: FL001–FL500 | E3: Unique identifier for each flight | F3: No | G3: Primary Key | H3: None
A4: flights | B4: flight_date | C4: Date | D4: 2022-01-01 to 2024-12-31 | E4: Date the flight was scheduled | F4: Yes (10 rows wrong format) | G4: – | H4: Check for DD/MM/YYYY vs YYYY-MM-DD
A5: flights | B5: airline | C5: Text | D5: Delta, United, American, Southwest, JetBlue, Alaska, Spirit, Frontier | E5: Airline operating the flight | F5: No | G5: – | H5: Some values in lowercase — standardize
A6: flights | B6: origin_city | C6: Text | D6: US city names | E6: City of departure | F6: No | G6: – | H6: None
A7: flights | B7: origin_code | C7: Text | D7: IATA 3-letter code | E7: Airport code of departure | F7: No | G7: Foreign Key → airports | H7: None
A8: flights | B8: destination_city | C8: Text | D8: US city names | E8: City of arrival | F8: No | G8: – | H8: None
A9: flights | B9: destination_code | C9: Text | D9: IATA 3-letter code | E9: Airport code of arrival | F9: No | G9: Foreign Key → airports | H9: None
A10: flights | B10: departure_time | C10: Text | D10: HH:MM (00:00–23:45) | E10: Scheduled departure time | F10: No | G10: – | H10: None
A11: flights | B11: arrival_time | C11: Text | D11: HH:MM (00:00–23:59) | E11: Scheduled arrival time | F11: No | G11: – | H11: None
A12: flights | B12: flight_duration_min | C12: Integer | D12: 90–480 | E12: Flight duration in minutes | F12: No | G12: – | H12: None
A13: flights | B13: distance_miles | C13: Integer | D13: 300–3000 | E13: Distance between origin and destination | F13: No | G13: – | H13: None
... A34: revenue | B34: payment_method | C34: Text | D34: Credit Card / Cash / Travel Points / Debit Card | E34: How ticket was paid | F34: No | G34: – | H34: None

Sheet 📝 Tasks
A1: 📝 STUDENT TASKS — DATA CLEANING, ANALYSIS, PIVOT TABLES & VISUALIZATION
A2: DATA CLEANING
A3: Task # | B3: Task | C3: Table | D3: Instructions
A4: DC-01 | B4: Fix inconsistent airline names (lowercase → Title Case) | C4: flights | D4: Use Find & Replace or a formula. All airline names should start with a capital letter. E.g. 'delta' → 'Delta'
A5: DC-02 | B5: Standardize the status column (UPPERCASE → Title Case) | C5: flights | D5: Values like 'ON-TIME' should be 'On-Time'. Use PROPER() or Find & Replace.
A6: DC-03 | B6: Fix date format inconsistencies | C6: flights | D6: Some dates are in DD/MM/YYYY format. Convert all to YYYY-MM-DD format.
A7: DC-04 | B7: Remove duplicate rows | C7: flights | D7: Identify and delete the 8 duplicate rows. Use Excel's 'Remove Duplicates' feature.
A8: DC-05 | B8: Handle missing ticket_price values | C8: flights | D8: Find blank cells in ticket_price. Replace with the median price per airline using MEDIAN() or fill manually.
A9: DC-06 | B9: Handle missing passengers_boarded values | C9: flights | D9: Replace missing values with the average passengers per class using AVERAGEIF().
A10: DC-07 | B10: Fix negative delay_minutes values | C10: flights | D10: Delay cannot be negative. Replace any negative delay with 0.
A11: DC-08 | B11: Fix outlier ticket prices | C11: flights | D11: Prices of -50, 0.5, 9999, and 15000 are likely errors. Replace with the average ticket price for the same class.
A12: DC-09 | B12: Handle missing fuel_cost in revenue | C12: revenue | D12: Fill missing fuel_cost values with the average fuel cost using AVERAGE().
A13: DC-10 | B13: Investigate zero total_revenue rows | C13: revenue | D13: Five rows have total_revenue = 0. Flag these rows and either correct or remove them.
A15: STATISTICAL ANALYSIS
A16: Task # | B16: Task | C16: Table | D16: Instructions
A17: SA-01 | B17: Calculate basic statistics for ticket_price | C17: flights | D17: Find the MIN, MAX, AVERAGE, MEDIAN, and STDEV of ticket_price. Use Excel functions.
A18: SA-02 | B18: Count flights by status | C18: flights | D18: Count how many flights are On-Time, Delayed, and Cancelled using COUNTIF().
A19: SA-03 | B19: Calculate average delay by airline | C19: flights | D19: Use AVERAGEIF() to find the average delay_minutes for each airline.
A20: SA-04 | B20: Find the busiest routes | C20: flights | D20: Combine origin_city and destination_city. Count occurrences to find the top 5 busiest routes.
A21: SA-05 | B21: Calculate average occupancy rate | C21: flights | D21: Occupancy = passengers_boarded / seats_available * 100. Create a new column and compute the average.
A22: SA-06 | B22: Find total and average profit by airline | C22: revenue | D22: Use SUMIF() and AVERAGEIF() to aggregate profit by airline (join via flight_id).
A23: SA-07 | B23: Calculate revenue per mile | C23: revenue | D23: Create a new column: revenue_per_mile = total_revenue / distance_miles (join flights table).
A24: SA-08 | B24: Find the airport with the most departures | C24: flights | D24: Count origin_code occurrences to find the top 3 busiest departure airports.
A26: PIVOT TABLES
A27: Task # | B27: Task | C27: Table | D27: Instructions
A28: PT-01 | B28: Flights by Airline and Status | C28: flights | D28: Create a pivot table showing count of flights for each airline, broken down by status (On-Time/Delayed/Cancelled).
A29: PT-02 | B29: Average Ticket Price by Class and Airline | C29: flights | D29: Rows = Airline, Columns = Class. Values = Average ticket_price.
A30: PT-03 | B30: Total Revenue by Airline | C30: revenue | D30: Join flights and revenue. Pivot total_revenue summed by airline.
A31: PT-04 | B31: Monthly Flight Count Trend | C31: flights | D31: Extract Month from flight_date. Rows = Month, Values = Count of flights.
A32: PT-05 | B32: Average Delay by Origin City | C32: flights | D32: Rows = origin_city. Values = Average delay_minutes. Sort descending.
A33: PT-06 | B33: Profit by Payment Method | C33: revenue | D33: Rows = payment_method. Values = SUM of profit. Sort by highest profit.
A35: DATA VISUALIZATION
A36: Task # | B36: Task | C36: Chart Type | D36: Instructions
A37: DV-01 | B37: Flight Status Distribution | C37: Pie Chart | D37: Show the proportion of On-Time vs Delayed vs Cancelled flights.
A38: DV-02 | B38: Average Ticket Price by Class | C38: Bar Chart | D38: Compare average ticket price across Economy, Business, and First Class.
A39: DV-03 | B39: Monthly Flights Over Time | C39: Line Chart | D39: Show how the number of flights changed month-by-month across 2022–2024.
A40: DV-04 | B40: Top 5 Airlines by Total Revenue | C40: Horizontal Bar Chart | D40: Rank airlines from highest to lowest total revenue.
A41: DV-05 | B41: Delay Minutes Distribution | C41: Histogram | D41: Show the distribution of delay_minutes to spot common delay ranges.
A42: DV-06 | B42: Occupancy Rate by Airline | C42: Column Chart | D42: Compare average occupancy rate (%) across airlines.
A43: DV-07 | B43: Profit vs Fuel Cost Scatter | C43: Scatter Plot | D43: Plot fuel_cost (x) vs profit (y) to identify any relationship.
...

Sheet Stat Analysis
A5: Calculate basic statistics for ticket_price | F5: Count flights by status | H5: Calculate average delay by airline | M5: Find the busiest routes
B8: Statistics | C8: Ticket Price | F8: Status | G8: Count | I8: Airline | J8: Average Delay
B9: Average (AVERAGE) | C9: =AVERAGE('✈ Flights (2)'!M2:M501) -> 619.22447 | F9: On-Time | G9: =COUNTIF('✈ Flights (2)'!$R$2:$R$501,"On-Time") -> 335 | I9: Delta | J9: =AVERAGEIF('✈ Flights (2)'!$C$2:$C$501,"Delta",'✈ Flights (2)'!T2:T501) -> 24.779661 | M9: Routes | N9: Count of Flight Id
B10: Median (MEDIAN) | C10: =MEDIAN('✈ Flights (2)'!M2:M501) -> 590.545 | F10: Delayed | G10: =COUNTIF('✈ Flights (2)'!$R$2:$R$501,"Delayed") -> 139 | I10: Southwest | J10: =AVERAGEIF('✈ Flights (2)'!$C$2:$C$501,"Southwest",'✈ Flights (2)'!T2:T501) -> 32 | M10: Chicago → Boston | N10: 7
B11: Std Deviation (STDEV) | C11: =STDEV('✈ Flights (2)'!M2:M501) -> 302.66384 | F11: Cancelled | G11: =COUNTIF('✈ Flights (2)'!$R$2:$R$501,"Cancelled") -> 26 | I11: Alaska | J11: =AVERAGEIF('✈ Flights (2)'!$C$2:$C$501,"Alaska",'✈ Flights (2)'!T2:T501) -> 25.754098 | M11: San Francisco → Minneapolis | N11: 5
B12: Minimum (MIN) | C12: =MIN('✈ Flights (2)'!M2:M501) -> 86.84 | I12: American | J12: =AVERAGEIF('✈ Flights (2)'!$C$2:$C$501,"American",'✈ Flights (2)'!T2:T501) -> 24.134328 | M12: San Diego → Chicago | N12: 5
B13: Maximum (MAX) | C13: =MAX('✈ Flights (2)'!M2:M501) -> 1196.58 | I13: Spirit | J13: =AVERAGEIF('✈ Flights (2)'!$C$2:$C$501,"Spirit",'✈ Flights (2)'!T2:T501) -> 31.686567 | M13: Houston → Las Vegas | N13: 5
I14: United | J14: =AVERAGEIF('✈ Flights (2)'!$C$2:$C$501,"United",'✈ Flights (2)'!T2:T501) -> 25.444444 | M14: Chicago → Detroit | N14: 5
A15: Calculate average occupancy rate | I15: Frontier | J15: =AVERAGEIF('✈ Flights (2)'!$C$2:$C$501,"Frontier",'✈ Flights (2)'!T2:T501) -> 18.8125 | M15: Charlotte → San Francisco | N15: 5
C16: =AVERAGE('✈ Flights (2)'!Q2:Q501) -> 62.326738 | I16: JetBlue | J16: =AVERAGEIF('✈ Flights (2)'!$C$2:$C$501,"JetBlue",'✈ Flights (2)'!T2:T501) -> 17.779661 | M16: Charlotte → Newark | N16: 5
M17: Newark → Houston | N17: 4
M18: New York → San Francisco | N18: 4
A19: Find total and average profit by airline | M19: Miami → Chicago | N19: 4
M20: Los Angeles → Phoenix | N20: 4
M21: Detroit → Chicago | N21: 4
M22: Denver → San Diego | N22: 4
M23: Denver → Houston | N23: 4
B24: Airline | C24: Total Profit | D24: Average Profit | M24: Dallas → Las Vegas | N24: 4
B25: Delta | C25: =SUMIF('💰 Revenue (2)'!$D$2:$D$502,B25,'💰 Revenue (2)'!$J$2:$J$502) -> 3416073.6 | D25: =AVERAGEIF('💰 Revenue (2)'!$D$2:$D$502,B25,'💰 Revenue (2)'!$J$2:$J$502) -> 57899.553 | M25: Chicago → Seattle | N25: 4
B26: Southwest | C26: =SUMIF('💰 Revenue (2)'!$D$2:$D$502,B26,'💰 Revenue (2)'!$J$2:$J$502) -> 4169184.8 | D26: =AVERAGEIF('💰 Revenue (2)'!$D$2:$D$502,B26,'💰 Revenue (2)'!$J$2:$J$502) -> 60422.968 | M26: Chicago → Los Angeles | N26: 4
B27: Alaska | C27: =SUMIF('💰 Revenue (2)'!$D$2:$D$502,B27,'💰 Revenue (2)'!$J$2:$J$502) -> 3712098 | D27: =AVERAGEIF('💰 Revenue (2)'!$D$2:$D$502,B27,'💰 Revenue (2)'!$J$2:$J$502) -> 60854.066 | F27: 6 | M27: Chicago → Atlanta | N27: 4
B28: American | C28: =SUMIF('💰 Revenue (2)'!$D$2:$D$502,B28,'💰 Revenue (2)'!$J$2:$J$502) -> 3141979 | D28: =AVERAGEIF('💰 Revenue (2)'!$D$2:$D$502,B28,'💰 Revenue (2)'!$J$2:$J$502) -> 46895.209 | G28: =AVERAGE('💰 Revenue (2)'!$F$2:$F$502) -> 69.596997 | M28: Boston → Newark | N28: 4
B29: Spirit | C29: =SUMIF('💰 Revenue (2)'!$D$2:$D$502,B29,'💰 Revenue (2)'!$J$2:$J$502) -> 4111871.5 | D29: =AVERAGEIF('💰 Revenue (2)'!$D$2:$D$502,B29,'💰 Revenue (2)'!$J$2:$J$502) -> 61371.217 | M29: Atlanta → New York | N29: 4
B30: United | C30: =SUMIF('💰 Revenue (2)'!$D$2:$D$502,B30,'💰 Revenue (2)'!$J$2:$J$502) -> 3426879.1 | D30: =AVERAGEIF('💰 Revenue (2)'!$D$2:$D$502,B30,'💰 Revenue (2)'!$J$2:$J$502) -> 63460.724 | M30: Atlanta → Chicago | N30: 4
B31: Frontier | C31: =SUMIF('💰 Revenue (2)'!$D$2:$D$502,B31,'💰 Revenue (2)'!$J$2:$J$502) -> 3299355.6 | D31: =AVERAGEIF('💰 Revenue (2)'!$D$2:$D$502,B31,'💰 Revenue (2)'!$J$2:$J$502) -> 51552.431 | G31: Find the airport with the most departures | M31: Atlanta → Charlotte | N31: 4
B32: JetBlue | C32: =SUMIF('💰 Revenue (2)'!$D$2:$D$502,B32,'💰 Revenue (2)'!$J$2:$J$502) -> 2910867.2 | D32: =AVERAGEIF('💰 Revenue (2)'!$D$2:$D$502,B32,'💰 Revenue (2)'!$J$2:$J$502) -> 49336.732 | F32: 7 | G32: ATL (Atlanta) — 35 departures | M32: Seattle → Orlando | N32: 3
G33: LAX (Los Angeles) — 32 departures | M33: Seattle → Chicago | N33: 3
G34: SAN (San Diego) — 30 departures | M34: San Francisco → Detroit | N34: 3
B35: average ticket price per class | M35: San Francisco → Chicago | N35: 3
M36: San Diego → Newark | N36: 3
B37: Class | C37: Average Price | M37: San Diego → Los Angeles | N37: 3
B38: Economy | C38: =AVERAGEIF('✈ Flights (2)'!$N$2:$N$501,"Economy",'✈ Flights (2)'!$M$2:$M$501) -> 586.99406 | M38: San Diego → Dallas | N38: 3
B39: Business | C39: =AVERAGEIF('✈ Flights (2)'!$N$2:$N$501,"Business",'✈ Flights (2)'!$M$2:$M$501) -> 624.39863 | M39: Phoenix → Atlanta | N39: 3
B40: First Class | C40: =AVERAGEIF('✈ Flights (2)'!$N$2:$N$501,"First Class",'✈ Flights (2)'!$M$2:$M$501) -> 634.1065 | M40: Orlando → San Francisco | N40: 3
M41: Orlando → Minneapolis | N41: 3
M42: Minneapolis → San Francisco | N42: 3
B43: Top 5 Airlines by Total Revenue | M43: Minneapolis → San Diego | N43: 3
M44: Minneapolis → Newark | N44: 3
B45: Airline | C45: Sum of Total Revenue | M45: Minneapolis → Chicago | N45: 3
B46: United | C46: 5204994.6 | M46: Miami → Houston | N46: 3
...

Sheet Pivot Tables
B2: Flights by Airline and Status
B5: Count of Flight Id | C5: Status
B6: Airline | C6: Cancelled | D6: Delayed | E6: On-Time
B7: Alaska | C7: 5 | D7: 15 | E7: 41
B8: American | C8: 6 | D8: 17 | E8: 44
B9: Delta | C9: 3 | D9: 17 | E9: 39
B10: Frontier | C10: 3 | D10: 16 | E10: 45
B11: Jetblue | C11: 1 | D11: 14 | E11: 44
B12: Southwest | C12: 3 | D12: 22 | E12: 44
B13: Spirit | C13: 2 | D13: 22 | E13: 43
B14: United | C14: 3 | D14: 16 | E14: 35
B19: Average Ticket Price by Class and Airline
B22: Average of Ticket Price | C22: Class
B23: Airline | C23: Business | D23: Economy | E23: First Class | F23: Unknown
B24: Alaska | C24: 588.10542 | D24: 651.575 | E24: 698.95376 | F24: 778.62667
B25: American | C25: 541.48442 | D25: 592.355 | E25: 592.22577 | F25: 637.648
B26: Delta | C26: 727.19395 | D26: 620.11133 | E26: 563.63543 | F26: 650.445
B27: Frontier | C27: 494.50313 | D27: 528.23924 | E27: 592.708 | F27: 765.79
B28: Jetblue | C28: 506.3875 | D28: 481.76389 | E28: 706.0313 | F28: 345.135
B29: Southwest | C29: 705.82045 | D29: 612.6366 | E29: 624.73875 | F29: 797.845
B30: Spirit | C30: 702.97252 | D30: 617.23211 | E30: 608.42706 | F30: 665.20333
B31: United | C31: 685.1283 | D31: 632.71167 | E31: 691.74429 | F31: 826.115
B41: Monthly Flight Count Trend
B46: Year-MONTH | C46: Count of Flight Id
B47: 2022-01 | C47: 12
B48: 2022-02 | C48: 11
B49: 2022-03 | C49: 17
B50: 2022-04 | C50: 17
B51: 2022-05 | C51: 11
B52: 2022-06 | C52: 18
B53: 2022-07 | C53: 21
B54: 2022-08 | C54: 14
B55: 2022-09 | C55: 14
B56: 2022-10 | C56: 18
B57: 2022-11 | C57: 15
B58: 2022-12 | C58: 12
... B82: 2024-12 | C82: 16
C86: Total Revenue by Airline
F89: Airline | G89: Sum of Total Revenue
F90: Southwest | G90: 6470138.4
...

Sheet Visulization
B2: Flight Status Distribution — Pie Chart
C43: Monthly Flights Over Time — Line Chart
C65: Top 5 Airlines by Total Revenue
D84: Delay Minutes Distribution
D121: Profit vs Fuel Cost — Scatter Plot
C139: Revenue Breakdown by Top 8 Airports

Sheet Dashboard
D6: TOTAL FLIGHTS | G6: Total Revenue | K6: Avg Occupancy Rate | O6: Avg Delay
D7: =COUNTA('✈ Flights (2)'!$A$2:A$501) -> 500 | G7: =SUM('💰 Revenue (2)'!$E$2:$E$5) -> 436269.86 | K7: =AVERAGE('✈ Flights (2)'!$Q$2:$Q$501) -> 62.326738 | O7: =AVERAGE('✈ Flights (2)'!$T$2:$T$501) -> 25.216
